LogEntry_0:
    exception:
        message: "AttributeError: 'module' object has no attribute 'VERSION'"
        traceback: ['  File "C:\\Users\\christopherb\\AppData\\Local\\conda\\conda\\envs\\mpatch\\lib\\runpy.py", line 174, in _run_module_as_main\n    "__main__", fname, loader, pkg_name)\n', '  File "C:\\Users\\christopherb\\AppData\\Local\\conda\\conda\\envs\\mpatch\\lib\\runpy.py", line 72, in _run_code\n    exec code in run_globals\n', '  File "c:\\users\\christopherb\\acq4\\acq4\\__main__.py", line 58, in <module>\n    man = Manager(argv=sys.argv[1:])\n', '  File "c:\\users\\christopherb\\acq4\\acq4\\Manager.py", line 120, in __init__\n    modules.importBuiltinClasses()\n', '  File "c:\\users\\christopherb\\acq4\\acq4\\modules\\__init__.py", line 57, in importBuiltinClasses\n    printExc(\'Error importing builtin module from %s\' % ff)\n', '  File "c:\\users\\christopherb\\acq4\\acq4\\util\\debug.py", line 43, in printExc\n    acq4.Manager.logExc(msg=msg, msgType=msgType)\n', '------- exception caught ---------->\n', 'Traceback (most recent call last):\n', '  File "c:\\users\\christopherb\\acq4\\acq4\\modules\\__init__.py", line 55, in importBuiltinClasses\n    mod = import_module(\'acq4.modules.\' + f)\n', '  File "C:\\Users\\christopherb\\AppData\\Local\\conda\\conda\\envs\\mpatch\\lib\\importlib\\__init__.py", line 37, in import_module\n    __import__(name)\n', '  File "c:\\users\\christopherb\\acq4\\acq4\\modules\\Imager\\__init__.py", line 2, in <module>\n    from .Imager import *\n', '  File "c:\\users\\christopherb\\acq4\\acq4\\modules\\Imager\\Imager.py", line 44, in <module>\n    from acq4.util import imaging\n', '  File "c:\\users\\christopherb\\acq4\\acq4\\util\\imaging\\__init__.py", line 9, in <module>\n    from .imaging_ctrl import ImagingCtrl\n', '  File "c:\\users\\christopherb\\acq4\\acq4\\util\\imaging\\imaging_ctrl.py", line 7, in <module>\n    from .record_thread import RecordThread\n', '  File "c:\\users\\christopherb\\acq4\\acq4\\util\\imaging\\record_thread.py", line 13, in <module>\n    from acq4.filetypes.ImageFile import *\n', '  File "c:\\users\\christopherb\\acq4\\acq4\\filetypes\\ImageFile.py", line 7, in <module>\n    if Image.VERSION == \'1.1.7\':\n']
    currentDir: None
    importance: 5
    timestamp: '2019.09.03 12:18:59'
    traceback: ['  File "C:\\Users\\christopherb\\AppData\\Local\\conda\\conda\\envs\\mpatch\\lib\\runpy.py", line 174, in _run_module_as_main\n    "__main__", fname, loader, pkg_name)\n', '  File "C:\\Users\\christopherb\\AppData\\Local\\conda\\conda\\envs\\mpatch\\lib\\runpy.py", line 72, in _run_code\n    exec code in run_globals\n', '  File "c:\\users\\christopherb\\acq4\\acq4\\__main__.py", line 58, in <module>\n    man = Manager(argv=sys.argv[1:])\n', '  File "c:\\users\\christopherb\\acq4\\acq4\\Manager.py", line 120, in __init__\n    modules.importBuiltinClasses()\n', '  File "c:\\users\\christopherb\\acq4\\acq4\\modules\\__init__.py", line 57, in importBuiltinClasses\n    printExc(\'Error importing builtin module from %s\' % ff)\n', '  File "c:\\users\\christopherb\\acq4\\acq4\\util\\debug.py", line 43, in printExc\n    acq4.Manager.logExc(msg=msg, msgType=msgType)\n', '------- exception caught ---------->\n']
    msgType: 'error'
    message: 'Error importing builtin module from c:\\users\\christopherb\\acq4\\acq4\\modules\\Imager'
    id: 1
LogEntry_1:
    exception: None
    currentDir: None
    importance: 5
    timestamp: '2019.09.03 12:19:00'
    msgType: 'status'
    message: 'Starting Manager configuration from c:\\users\\christopherb\\acq4\\config\\default.cfg'
    id: 2
LogEntry_2:
    exception: None
    currentDir: None
    importance: 5
    timestamp: '2019.09.03 12:19:00'
    msgType: 'status'
    message: '=== Device configuration complete ==='
    id: 3
LogEntry_3:
    exception: None
    currentDir: None
    importance: 5
    timestamp: '2019.09.03 12:19:00'
    msgType: 'status'
    message: '=== Setting base directory: C:\\users\\christopherb\\desktop\\GEVI ==='
    id: 4
LogEntry_4:
    exception: None
    currentDir: 'C:\\users\\christopherb\\desktop\\GEVI'
    importance: 8
    timestamp: '2019.09.03 12:19:00'
    msgType: 'warning'
    docs: ['userGuide/dataManagement.html#notes-and-logs']
    message: 'No log directory set. Log messages will not be stored.'
    id: 5
LogEntry_5:
    exception: None
    currentDir: 'C:\\users\\christopherb\\desktop\\GEVI'
    importance: 5
    timestamp: '2019.09.03 12:19:00'
    msgType: 'status'
    message: 'Manager configuration complete.'
    id: 6
LogEntry_6:
    exception: None
    currentDir: 'C:\\users\\christopherb\\desktop\\GEVI'
    importance: 9
    timestamp: '2019.09.03 12:19:00'
    msgType: 'status'
    message: u'ACQ4 version 0.9.3+gff689951 started.'
    id: 7
LogEntry_7:
    exception: None
    currentDir: 'C:\\users\\christopherb\\desktop\\GEVI'
    importance: 8
    timestamp: '2019.09.03 12:19:10'
    msgType: 'warning'
    docs: ['userGuide/dataManagement.html#notes-and-logs']
    message: 'No log directory set. Log messages will not be stored.'
    id: 8
LogEntry_8:
    exception: None
    currentDir: 'C:\\users\\christopherb\\desktop\\GEVI'
    importance: 8
    timestamp: '2019.09.03 13:42:11'
    msgType: 'warning'
    docs: ['userGuide/dataManagement.html#notes-and-logs']
    message: 'No log directory set. Log messages will not be stored.'
    id: 9
LogEntry_9:
    exception: None
    currentDir: 'C:\\users\\christopherb\\desktop\\GEVI'
    importance: 8
    timestamp: '2019.09.03 13:42:17'
    msgType: 'warning'
    docs: ['userGuide/dataManagement.html#notes-and-logs']
    message: 'No log directory set. Log messages will not be stored.'
    id: 10
LogEntry_10:
    exception: None
    currentDir: 'C:\\users\\christopherb\\desktop\\GEVI'
    importance: 8
    timestamp: '2019.09.03 13:42:31'
    msgType: 'warning'
    docs: ['userGuide/dataManagement.html#notes-and-logs']
    message: 'No log directory set. Log messages will not be stored.'
    id: 11
LogEntry_11:
    exception: None
    currentDir: 'C:\\users\\christopherb\\desktop\\GEVI'
    importance: 8
    timestamp: '2019.09.03 13:44:51'
    msgType: 'warning'
    docs: ['userGuide/dataManagement.html#notes-and-logs']
    message: 'No log directory set. Log messages will not be stored.'
    id: 12
LogEntry_12:
    exception:
        message: 'IndexError: index 0 is out of bounds for axis 0 with size 0'
        traceback: ['Traceback (most recent call last):\n', '  File "multipatch_analysis\\ui\\acq4_modules.py", line 339, in load_from_dm_clicked\n    self.ui.load_data(sel_dir)\n', '  File "multipatch_analysis\\ui\\vimaging.py", line 84, in load_data\n    self._load_data(seqDir)\n', '  File "multipatch_analysis\\ui\\vimaging.py", line 175, in _load_data\n    self.roi_changed(None)\n', '  File "multipatch_analysis\\ui\\vimaging.py", line 222, in roi_changed\n    self.update_sequence_analysis()\n', '  File "multipatch_analysis\\ui\\vimaging.py", line 274, in update_sequence_analysis\n    base_starti, base_stopi, test_starti, test_stopi, noise_starti, noise_stopi = self.time_indices(img_t)\n', '  File "multipatch_analysis\\ui\\vimaging.py", line 248, in time_indices\n    base_stopi = np.argwhere(time_vals >= base_stop)[0,0]\n']
    currentDir: 'C:\\users\\christopherb\\desktop\\GEVI'
    importance: 5
    timestamp: '2019.09.03 13:45:04'
    msgType: 'error'
    message: 'Unexpected error: '
    id: 13
LogEntry_13:
    exception: None
    currentDir: 'C:\\users\\christopherb\\desktop\\GEVI'
    importance: 9
    timestamp: '2019.09.03 16:41:06'
    msgType: 'status'
    message: 'Shutting Down.'
    id: 14
